<?xml version="1.0" encoding="utf-8"?>
<robot xmlns:xacro="http://www.ros.org/wiki/xacro" name="acamana">

  <!-- Define some constants -->
  <xacro:property name="PI" value="3.1415926535897931"/>

  <!-- Include Gazebo reference plugin -->
  <xacro:include filename="$(find acamana)/urdf/acamana.gazebo"/>

  <!-- Base Link -->
  <link name="base_link">
    <inertial>
      <origin xyz="-0.000410773784337879 -4.50102945727632E-06 0.000188079948723217" rpy="0 0 0" />
      <mass value="0.224252192432071" />
      <inertia
        ixx="0.000384367775648917"
        ixy="3.76312515381557E-08"
        ixz="-3.24905280224815E-09"
        iyy="0.00152650491504501"
        iyz="7.02452171299624E-11"
        izz="0.00189778395864725" />
    </inertial>
    <visual>
      <origin xyz="0 0 0" rpy="0 0 0" />
      <geometry>
        <mesh filename="package://acamana/meshes/base_link.STL" />
      </geometry>
      <material name="light_blue">
        <color rgba="0.792156862745098 0.819607843137255 0.933333333333333 1" />
      </material>
    </visual>
    <collision>
      <origin xyz="0 0 0" rpy="0 0 0" />
      <geometry>
        <mesh filename="package://acamana/meshes/base_link.STL" />
      </geometry>
    </collision>
  </link>

  <!-- Left Steering Hinge -->
  <link name="left_steering_hinge">
    <inertial>
      <origin xyz="-0.00214055518577709 0.0114938412169271 -0.00101430442705201" rpy="0 0 0" />
      <mass value="0.019320077665136" />
      <inertia
        ixx="3.65091233921692E-06"
        ixy="-3.8359376652168E-07"
        ixz="-4.31566026293577E-07"
        iyy="4.40274174328948E-06"
        iyz="-1.57348260942121E-07"
        izz="4.35327403175562E-06" />
    </inertial>
    <visual>
      <origin xyz="0 0 0" rpy="0 0 0" />
      <geometry>
        <mesh filename="package://acamana/meshes/left_steering_hinge.STL" />
      </geometry>
      <material name="light_blue" />
    </visual>
    <collision>
      <origin xyz="0 0 0" rpy="0 0 0" />
      <geometry>
        <mesh filename="package://acamana/meshes/left_steering_hinge.STL" />
      </geometry>
    </collision>
  </link>

  <joint name="left_steering_hinge_joint" type="revolute">
    <origin xyz="0.11123 0.063711 -0.00033469" rpy="0 0 0" />
    <parent link="base_link" />
    <child link="left_steering_hinge" />
    <axis xyz="0 0 1" />
    <limit lower="-0.785" upper="0.785" effort="1999.9" velocity="348.9" />
  </joint>

  <!-- Left Front Wheel -->
  <link name="left_front_wheel">
    <inertial>
      <origin xyz="2.69864139146314E-07 0.000974501012028089 7.43504567637335E-08" rpy="0 0 0" />
      <mass value="0.124188351717402" />
      <inertia
        ixx="0.000108426219461981"
        ixy="6.16641829591181E-10"
        ixz="6.14953076918742E-09"
        iyy="0.000198988759881268"
        iyz="-1.79345986661271E-11"
        izz="0.000108425295656723" />
    </inertial>
    <visual>
      <origin xyz="0 0 0" rpy="0 0 0" />
      <geometry>
        <mesh filename="package://acamana/meshes/left_front_wheel.STL" />
      </geometry>
      <material name="light_blue" />
    </visual>
    <collision>
      <origin xyz="0 0 0" rpy="0 0 0" />
      <geometry>
        <mesh filename="package://acamana/meshes/left_front_wheel.STL" />
      </geometry>
    </collision>
  </link>

  <joint name="left_front_wheel_joint" type="continuous">
    <origin xyz="0 0.047063 0" rpy="0 0 0" />
    <parent link="left_steering_hinge" />
    <child link="left_front_wheel" />
    <axis xyz="0 -1 0" />
    <limit effort="259.9" velocity="529.9" />
    <dynamics damping="0.1" friction="0.1"/>
  </joint>

  <!-- Right Steering Hinge -->
  <link name="right_steering_hinge">
    <inertial>
      <origin xyz="-0.00214065668285346 -0.0114939743395863 -0.00101615028127726" rpy="0 0 0" />
      <mass value="0.0193185139789688" />
      <inertia
        ixx="3.6507224134391E-06"
        ixy="3.83677614862953E-07"
        ixz="-4.31474916495668E-07"
        iyy="4.40170253054901E-06"
        iyz="1.57666090581151E-07"
        izz="4.3530528940828E-06" />
    </inertial>
    <visual>
      <origin xyz="0 0 0" rpy="0 0 0" />
      <geometry>
        <mesh filename="package://acamana/meshes/right_steering_hinge.STL" />
      </geometry>
      <material name="light_blue" />
    </visual>
    <collision>
      <origin xyz="0 0 0" rpy="0 0 0" />
      <geometry>
        <mesh filename="package://acamana/meshes/right_steering_hinge.STL" />
      </geometry>
    </collision>
  </link>

  <joint name="right_steering_hinge_joint" type="revolute">
    <origin xyz="0.11123 -0.063711 -0.00033469" rpy="0 0 0" />
    <parent link="base_link" />
    <child link="right_steering_hinge" />
    <axis xyz="0 0 1" />
    <limit lower="-0.785" upper="0.785" effort="1999.9" velocity="348.9" />
  </joint>

  <!-- Right Front Wheel -->
  <link name="right_front_wheel">
    <inertial>
      <origin xyz="-1.550417727883E-06 -0.000974395825432128 2.48294778512344E-06" rpy="0 0 0" />
      <mass value="0.124186468008551" />
      <inertia
        ixx="0.0001084386658304"
        ixy="8.2849214966896E-10"
        ixz="2.08769584709537E-08"
        iyy="0.000199003281991997"
        iyz="1.53854417197541E-09"
        izz="0.00010842819433505" />
    </inertial>
    <visual>
      <origin xyz="0 0 0" rpy="0 0 0" />
      <geometry>
        <mesh filename="package://acamana/meshes/right_front_wheel.STL" />
      </geometry>
      <material name="light_blue" />
    </visual>
    <collision>
      <origin xyz="0 0 0" rpy="0 0 0" />
      <geometry>
        <mesh filename="package://acamana/meshes/right_front_wheel.STL" />
      </geometry>
    </collision>
  </link>

  <joint name="right_front_wheel_joint" type="continuous">
    <origin xyz="0 -0.047063 0" rpy="0 0 0" />
    <parent link="right_steering_hinge" />
    <child link="right_front_wheel" />
    <axis xyz="0 -1 0" />
    <limit effort="259.9" velocity="529.9" />
    <dynamics damping="0.1" friction="0.1"/>
  </joint>

  <!-- Left Rear Wheel -->
  <link name="left_rear_wheel">
    <inertial>
      <origin xyz="1.48678928679757E-06 0.000974279188147756 -2.39603507424775E-06" rpy="0 0 0" />
      <mass value="0.124185768823433" />
      <inertia
        ixx="0.000108447186828646"
        ixy="9.3356109022442E-10"
        ixz="-7.51084978124662E-09"
        iyy="0.000198999670249457"
        iyz="2.67909684507298E-10"
        izz="0.000108415507605727" />
    </inertial>
    <visual>
      <origin xyz="0 0 0" rpy="0 0 0" />
      <geometry>
        <mesh filename="package://acamana/meshes/left_rear_wheel.STL" />
      </geometry>
      <material name="light_blue" />
    </visual>
    <collision>
      <origin xyz="0 0 0" rpy="0 0 0" />
      <geometry>
        <mesh filename="package://acamana/meshes/left_rear_wheel.STL" />
      </geometry>
    </collision>
  </link>

  <joint name="left_rear_wheel_joint" type="continuous">
    <origin xyz="-0.1021 0.11077 0" rpy="0 0 0" />
    <parent link="base_link" />
    <child link="left_rear_wheel" />
    <axis xyz="0 -1 0" />
    <limit effort="259.9" velocity="529.9" />
    <dynamics damping="0.1" friction="0.1"/>
  </joint>

  <!-- Right Rear Wheel -->
  <link name="right_rear_wheel">
    <inertial>
      <origin xyz="1.49354641822141E-06 -0.000974859994966409 -2.34500844404229E-06" rpy="0 0 0" />
      <mass value="0.12418629538773" />
      <inertia
        ixx="0.000108447659615878"
        ixy="8.73156228173837E-10"
        ixz="-8.57721842762821E-09"
        iyy="0.000199000738710147"
        iyz="3.07367743094142E-10"
        izz="0.000108416160865518" />
    </inertial>
    <visual>
      <origin xyz="0 0 0" rpy="0 0 0" />
      <geometry>
        <mesh filename="package://acamana/meshes/right_rear_wheel.STL" />
      </geometry>
      <material name="light_blue" />
    </visual>
    <collision>
      <origin xyz="0 0 0" rpy="0 0 0" />
      <geometry>
        <mesh filename="package://acamana/meshes/right_rear_wheel.STL" />
      </geometry>
    </collision>
  </link>

  <joint name="right_rear_wheel_joint" type="continuous">
    <origin xyz="-0.1021 -0.11077 0" rpy="0 0 0" />
    <parent link="base_link" />
    <child link="right_rear_wheel" />
    <axis xyz="0 -1 0" />
    <limit effort="259.9" velocity="529.9" />
    <dynamics damping="0.1" friction="0.1"/>
  </joint>

</robot> 